<?xml version="1.0"?>
<robot name="robot" xmlns:xacro="http://www.ros.org/wiki/xacro">
    <xacro:property name="params" value="${load_yaml('../urdf.yaml')}"/>
 
    <material name="red">
        <color rgba="1 0 0 1"/>
    </material>

    <material name="white"> 
        <color rgba="1 1 1 1"/>
    </material>

    <material name="black">
        <color rgba="0 0 0 1"/>
    </material>

    <material name="yellow">
        <color rgba="1 0.9 0 1"/>
    </material>



    <link name="base_link">
        <visual>
            <geometry>
                <cylinder length="0.05" radius="0.1"/>
            </geometry>
            <origin xyz="0 0 -0.025"/>
            <material name="black"/>
        </visual>
    </link>

    <link name="link1">
        <visual>
            <geometry>
                <box size="${params['i2']['link_x_size']} 0.025 0.025"/>
            </geometry>
            <origin xyz="${params['i2']['link_xyz']}" rpy="${params['i2']['link_rpy']}"/>
            <material name="blue"/>
        </visual>
    </link>

    <joint name="base_to_link1" type="revolute">
        <parent link="base_link"/>
        <child link="link1"/>
        <axis xyz="0 0 1"/>
        <origin xyz="${params['i1']['joint_xyz']}" rpy="${params['i1']['joint_rpy']}"/>
        <limit effort="1000.0" lower="-3" upper="3" velocity="0.5"/>
    </joint>


    <link name="link2">
        <visual>
            <geometry>
                <box size="${params['i3']['link_x_size']} 0.025 0.025"/>
            </geometry>
            <origin xyz="${params['i3']['link_xyz']}" rpy="${params['i3']['link_rpy']}"/>
            <material name="white"/>
        </visual>
    </link>

    <joint name="link1_to_link2" type="revolute">
        <parent link="link1"/>
        <child link="link2"/>
        <axis xyz="0 0 1"/>
        <origin xyz="${params['i2']['joint_xyz']}" rpy="${params['i2']['joint_rpy']}"/>
        <limit effort="1000.0" lower="-3" upper="3" velocity="0.5"/>
    </joint>


    <link name="link3">
        <visual>
            <geometry>
                <cylinder length="0.35" radius="0.01"/>
            </geometry>
            <origin xyz="0 0 -0.175" rpy="0 0 0"/>
            <material name="magenta"/>
        </visual>
    </link>

    <joint name="link2_to_link3" type="fixed">
        <parent link="link2"/>
        <child link="link3"/>
        <axis xyz="0 0 1"/>
        <origin xyz="${params['i3']['joint_xyz']}" rpy="${params['i3']['joint_rpy']}"/>
        <limit effort="1000.0" lower="0" upper="0.3" velocity="0.5"/>
    </joint>

</robot>
