<?xml version="1.0"?>
<robot name="roBOT" xmlns:xacro="http://www.ros.org/wiki/xacro">
    <xacro:property name="params" value="${load_yaml('../src/out.yaml')}"/>
    <xacro:property name="join_radius" value="0.1" />
    <xacro:property name="join_height" value="0.1" />
    <xacro:property name="box_w" value="0.2" />
    <xacro:property name="box_l" value="0.2" />

    <material name="blue">
      <color rgba="0 0 1 1"/>
    </material>

    <material name="black">
      <color rgba="0 0 0 1"/>
    </material>
    <material name="yellow">
      <color rgba="1 0.3 0 1"/>
    </material>

    <link name="base_link">
    <visual>
      <geometry>
        <box size="${box_w} ${box_l} ${box_w}"/>
      </geometry>
      <origin xyz="0 0 0" rpy="${params['firstRow']['rpy']}"/>
      <material name="yellow"/>
    </visual>
    </link>

    <link name="link1">
    <visual>
      <geometry>
         <box size="${box_w} ${box_l} ${params['firstRow']['len']}"/>
      
      </geometry>
      <origin xyz="${params['firstRow']['xyz']}" rpy="0.0 0.0 0.0"/>
      <material name="yellow"/>
    </visual>
    </link>

    <link name="link2">
    <visual>
      <geometry>
        <box size="${box_w} ${box_l} ${params['secondRow']['len']}"/>
      </geometry>
      <origin xyz="${params['secondRow']['xyz']}" rpy="1.57 0.0 1.57"/>
      <material name="yellow"/>
    </visual>
    </link>

    <link name="link3">
    <visual>
      <geometry>
        <box size="${box_w} ${box_l} ${params['thirdRow']['len']}"/>
      </geometry>
      <origin xyz="${params['thirdRow']['xyz']}" rpy="1.57 0.0 1.57"/>
      <material name="yellow"/>
    </visual>
    </link>


    <link name="link4">
    <visual>
      <geometry>
        <box size="${box_w} ${box_l} 0.5"/>
      </geometry>
      <origin xyz="0.25 0 0" rpy="1.57 0.0 1.57"/>
      <material name="blue"/>
    </visual>
    </link>

    <link name="join1">
    <visual>
      <geometry>
        <cylinder length="${join_height}" radius="${join_radius}"/>
      </geometry>
      <origin xyz="0 0 0" rpy="${params['secondRow']['rpy']}"/>
      <material name="black"/>
    </visual>
    </link>

    <link name="join2">
    <visual>
      <geometry>
        <cylinder length="${join_height}" radius="0"/>
      </geometry>
      <origin xyz="0 0 0" rpy="${params['thirdRow']['rpy']}"/>
      <material name="black"/>
    </visual>
    </link>

    <link name="join3">
    <visual>
      <geometry>
        <cylinder length="${join_height}" radius="0"/>
      </geometry>
      <origin xyz="0 0 0" rpy="0 0 0"/>
      <material name="black"/>
    </visual>
    </link>

    <link name="join4">
    <visual>
      <geometry>
        <sphere radius="0"/>
      </geometry>
      <origin xyz="0 0 0" rpy="0 0 0"/>
      <material name="blue"/>
    </visual>
    </link>

    <joint name="base_link1" type="fixed">
        <parent link="base_link"/>
        <child link="link1"/>
        <origin xyz="0 0 0" rpy="${params['firstRow']['rpy']}"/>
         
        <axis xyz="0 0 1"/>
    </joint>

    <joint name="link1_join1" type="prismatic">
        <parent link="link1"/>
        <child link="join1"/>
        <origin xyz="0 0 ${params['firstRow']['len']}" rpy="0 0 0"/>
  <limit effort="1000.0" lower="${params['firstRow']['limit']}" upper="0" velocity="0.5"/>
        <axis xyz="0 0 1"/>
    </joint>

    <joint name="join1_link2" type="fixed">
        <parent link="join1"/>
        <child link="link2"/>
        <origin xyz="0 0 0" rpy="${params['secondRow']['rpy']}"/>
        <axis xyz="0 0 1"/>
    </joint>

    <joint name="link2_join2" type="fixed">
        <parent link="link2"/>
        <child link="join2"/>
        <origin xyz="${params['secondRow']['len']} 0 0" rpy="0 0 0"/>
         <limit effort="1000.0" lower="-3.14 " upper="3.14" velocity="0.5"/>
        <axis xyz="0 0 1"/>
    </joint>

    <joint name="join2_link3" type="continuous">
        <parent link="join2"/>
        <child link="link3"/>
        <origin xyz="0 0 0 " rpy="${params['thirdRow']['rpy']}"/>
         <limit effort="1000.0" lower="-3.14 " upper="3.14" velocity="0.5"/>
        <axis xyz="0 0 1"/>
    </joint>

    <joint name="link3_join3" type="fixed">
        <parent link="link3"/>
        <child link="join3"/>
        <origin xyz="${params['thirdRow']['len']} 0 0" rpy="0 0 0"/>

        <axis xyz="0 0 1"/>
    </joint>

    <joint name="join3_link4" type="continuous">
        <parent link="join3"/>
        <child link="link4"/>
        <origin xyz="0 0 0 " rpy="${params['thirdRow']['rpy']}"/>
         <limit effort="1000.0" lower="-3.14 " upper="3.14" velocity="0.5"/>
        <axis xyz="0 0 1"/>
    </joint>

    <joint name="link4_join4" type="fixed">
        <parent link="link4"/>
        <child link="join4"/>
        <origin xyz="0.5 0 0" rpy="0 0 0"/>

        <axis xyz="0 0 1"/>
    </joint>


</robot>
